<?xml version="1.0" ?>
<!-- =================================================================================== -->
<!-- |    This document was autogenerated by xacro from /home/zyb/ros2_ws/src/bupt_dog_description/xacro/robot.xacro | -->
<!-- |    EDITING THIS FILE BY HAND IS NOT RECOMMENDED                                 | -->
<!-- =================================================================================== -->
<robot name="bupt_dog">
  <link name="base">
    <visual>
      <origin rpy="0 0 0" xyz="0 0 0"/>
      <geometry>
        <box size="0.001 0.001 0.001"/>
      </geometry>
    </visual>
  </link>
  <joint name="floating_base" type="fixed">
    <origin rpy="0 0 0" xyz="0 0 0"/>
    <parent link="base"/>
    <child link="body"/>
  </joint>
  <link name="body">
    <visual>
      <origin rpy="0 0 0" xyz="0 0 0"/>
      <geometry>
        <box size="0.362 0.26242 0.103"/>
      </geometry>
    </visual>
    <collision>
      <origin rpy="0 0 0" xyz="0 0 0"/>
      <geometry>
        <box size="0.362 0.26242 0.103"/>
      </geometry>
    </collision>
    <inertial>
      <origin rpy="0 0 0" xyz="0.0 0.0 0.0"/>
      <mass value="7.863"/>
      <inertia ixx="0.037221" ixy="0.0" ixz="0.0" iyy="0.145629" iyz="0.0" izz="0.16547"/>
    </inertial>
  </link>
  <joint name="FL_X_joint" type="revolute">
    <origin rpy="0 0 0" xyz="0.240292 0.056 0"/>
    <parent link="body"/>
    <child link="FL_X"/>
    <axis xyz="1 0 0"/>
    <limit effort="33.5" lower="-0.8028514559173915" upper="0.8028514559173915" velocity="21"/>
  </joint>
  <link name="FL_X">
    <visual>
      <origin rpy="1.5707963267948966 0.0 0.0" xyz="0.0 0.043425 0.0"/>
      <geometry>
        <cylinder length="0.08685" radius="0.046"/>
      </geometry>
    </visual>
    <collision>
      <origin rpy="1.5707963267948966 0.0 0.0" xyz="0.0 0.043425 0.0"/>
      <geometry>
        <cylinder length="0.08685" radius="0.046"/>
      </geometry>
    </collision>
    <inertial>
      <origin rpy="0 0 0" xyz="0.002 0.05 0.0"/>
      <mass value="1.508"/>
      <inertia ixx="0.003" ixy="0.0" ixz="0.0" iyy="0.002" iyz="0.0" izz="0.003"/>
    </inertial>
  </link>
  <joint name="FL_Y_joint" type="revolute">
    <origin rpy="0.0 0.0 0.0" xyz="0.0 0.0991 0.0"/>
    <parent link="FL_X"/>
    <child link="FL_Y"/>
    <axis xyz="0 1 0"/>
    <limit effort="33.5" lower="-1.0471975511965976" upper="4.1887902047863905" velocity="21"/>
  </joint>
  <link name="FL_Y">
    <visual>
      <origin rpy="0.0 0.0 0.0" xyz="0.0 0.0 -0.1075"/>
      <geometry>
        <box size="0.034 0.0245 0.215"/>
      </geometry>
    </visual>
    <collision>
      <origin rpy="0.0 0.0 0.0" xyz="0.0 0.0 -0.1075"/>
      <geometry>
        <box size="0.034 0.0245 0.215"/>
      </geometry>
    </collision>
    <inertial>
      <origin rpy="0 0 0" xyz="0.002 0.014 -0.056"/>
      <mass value="0.272"/>
      <inertia ixx="0.001" ixy="0.0" ixz="0.0" iyy="0.002" iyz="0.0" izz="1e-05"/>
    </inertial>
  </link>
  <joint name="FL_KNEE_joint" type="revolute">
    <origin rpy="0.0 0.0 0.0" xyz="0.0 0.0 -0.215"/>
    <parent link="FL_Y"/>
    <child link="FL_KNEE"/>
    <axis xyz="0 1 0"/>
    <limit effort="33.5" lower="-2.6965336943312392" upper="-0.9162978572970231" velocity="21"/>
  </joint>
  <link name="FL_KNEE">
    <visual>
      <origin rpy="0.0 0.0 0.0" xyz="0.0 0.0 -0.104"/>
      <geometry>
        <box size="0.016 0.016 0.208"/>
      </geometry>
    </visual>
    <collision>
      <origin rpy="0.0 0.0 0.0" xyz="0.0 0.0 -0.104"/>
      <geometry>
        <box size="0.016 0.016 0.208"/>
      </geometry>
    </collision>
    <inertial>
      <origin rpy="0 0 0" xyz="0.0 0.0 -0.086"/>
      <mass value="0.157"/>
      <inertia ixx="0.001" ixy="0.0" ixz="0.0" iyy="0.001" iyz="0.0" izz="1e-05"/>
    </inertial>
  </link>
  <joint name="FL_FOOT_joint" type="fixed">
    <origin rpy="0.0 0.0 0.0" xyz="0.0 0.0 -0.22799999999999998"/>
    <parent link="FL_KNEE"/>
    <child link="FL_FOOT"/>
  </joint>
  <link name="FL_FOOT">
    <visual>
      <origin rpy="0 0 0" xyz="0 0 0"/>
      <geometry>
        <sphere radius="0.02"/>
      </geometry>
    </visual>
    <collision>
      <origin rpy="0 0 0" xyz="0 0 0"/>
      <geometry>
        <sphere radius="0.02"/>
      </geometry>
    </collision>
    <inertial>
      <mass value="0.06"/>
      <inertia ixx="9.600000000000001e-06" ixy="0.0" ixz="0.0" iyy="9.600000000000001e-06" iyz="0.0" izz="9.600000000000001e-06"/>
    </inertial>
  </link>
  <joint name="FR_X_joint" type="revolute">
    <origin rpy="0 0 0" xyz="0.240292 -0.056 0"/>
    <parent link="body"/>
    <child link="FR_X"/>
    <axis xyz="1 0 0"/>
    <limit effort="33.5" lower="-0.8028514559173915" upper="0.8028514559173915" velocity="21"/>
  </joint>
  <link name="FR_X">
    <visual>
      <origin rpy="1.5707963267948966 0.0 0.0" xyz="0.0 -0.043425 0.0"/>
      <geometry>
        <cylinder length="0.08685" radius="0.046"/>
      </geometry>
    </visual>
    <collision>
      <origin rpy="1.5707963267948966 0.0 0.0" xyz="0.0 -0.043425 0.0"/>
      <geometry>
        <cylinder length="0.08685" radius="0.046"/>
      </geometry>
    </collision>
    <inertial>
      <origin rpy="0 0 0" xyz="0.002 -0.05 0.0"/>
      <mass value="1.508"/>
      <inertia ixx="0.003" ixy="0.0" ixz="0.0" iyy="0.002" iyz="0.0" izz="0.003"/>
    </inertial>
  </link>
  <joint name="FR_Y_joint" type="revolute">
    <origin rpy="0.0 0.0 0.0" xyz="0.0 -0.0991 0.0"/>
    <parent link="FR_X"/>
    <child link="FR_Y"/>
    <axis xyz="0 1 0"/>
    <limit effort="33.5" lower="-1.0471975511965976" upper="4.1887902047863905" velocity="21"/>
  </joint>
  <link name="FR_Y">
    <visual>
      <origin rpy="0.0 0.0 0.0" xyz="0.0 0.0 -0.1075"/>
      <geometry>
        <box size="0.034 0.0245 0.215"/>
      </geometry>
    </visual>
    <collision>
      <origin rpy="0.0 0.0 0.0" xyz="0.0 0.0 -0.1075"/>
      <geometry>
        <box size="0.034 0.0245 0.215"/>
      </geometry>
    </collision>
    <inertial>
      <origin rpy="0 0 0" xyz="0.002 -0.014 -0.056"/>
      <mass value="0.272"/>
      <inertia ixx="0.001" ixy="0.0" ixz="0.0" iyy="0.002" iyz="0.0" izz="1e-05"/>
    </inertial>
  </link>
  <joint name="FR_KNEE_joint" type="revolute">
    <origin rpy="0.0 0.0 0.0" xyz="0.0 0.0 -0.215"/>
    <parent link="FR_Y"/>
    <child link="FR_KNEE"/>
    <axis xyz="0 1 0"/>
    <limit effort="33.5" lower="-2.6965336943312392" upper="-0.9162978572970231" velocity="21"/>
  </joint>
  <link name="FR_KNEE">
    <visual>
      <origin rpy="0.0 0.0 0.0" xyz="0.0 0.0 -0.104"/>
      <geometry>
        <box size="0.016 0.016 0.208"/>
      </geometry>
    </visual>
    <collision>
      <origin rpy="0.0 0.0 0.0" xyz="0.0 0.0 -0.104"/>
      <geometry>
        <box size="0.016 0.016 0.208"/>
      </geometry>
    </collision>
    <inertial>
      <origin rpy="0 0 0" xyz="0.0 0.0 -0.086"/>
      <mass value="0.157"/>
      <inertia ixx="0.001" ixy="0.0" ixz="0.0" iyy="0.001" iyz="0.0" izz="1e-05"/>
    </inertial>
  </link>
  <joint name="FR_FOOT_joint" type="fixed">
    <origin rpy="0.0 0.0 0.0" xyz="0.0 0.0 -0.22799999999999998"/>
    <parent link="FR_KNEE"/>
    <child link="FR_FOOT"/>
  </joint>
  <link name="FR_FOOT">
    <visual>
      <origin rpy="0 0 0" xyz="0 0 0"/>
      <geometry>
        <sphere radius="0.02"/>
      </geometry>
    </visual>
    <collision>
      <origin rpy="0 0 0" xyz="0 0 0"/>
      <geometry>
        <sphere radius="0.02"/>
      </geometry>
    </collision>
    <inertial>
      <mass value="0.06"/>
      <inertia ixx="9.600000000000001e-06" ixy="0.0" ixz="0.0" iyy="9.600000000000001e-06" iyz="0.0" izz="9.600000000000001e-06"/>
    </inertial>
  </link>
  <joint name="HL_X_joint" type="revolute">
    <origin rpy="0 0 0" xyz="-0.240292 0.056 0"/>
    <parent link="body"/>
    <child link="HL_X"/>
    <axis xyz="1 0 0"/>
    <limit effort="33.5" lower="-0.8028514559173915" upper="0.8028514559173915" velocity="21"/>
  </joint>
  <link name="HL_X">
    <visual>
      <origin rpy="1.5707963267948966 0.0 0.0" xyz="0.0 0.043425 0.0"/>
      <geometry>
        <cylinder length="0.08685" radius="0.046"/>
      </geometry>
    </visual>
    <collision>
      <origin rpy="1.5707963267948966 0.0 0.0" xyz="0.0 0.043425 0.0"/>
      <geometry>
        <cylinder length="0.08685" radius="0.046"/>
      </geometry>
    </collision>
    <inertial>
      <origin rpy="0 0 0" xyz="0.002 0.05 0.0"/>
      <mass value="1.508"/>
      <inertia ixx="0.003" ixy="0.0" ixz="0.0" iyy="0.002" iyz="0.0" izz="0.003"/>
    </inertial>
  </link>
  <joint name="HL_Y_joint" type="revolute">
    <origin rpy="0.0 0.0 0.0" xyz="0.0 0.0991 0.0"/>
    <parent link="HL_X"/>
    <child link="HL_Y"/>
    <axis xyz="0 1 0"/>
    <limit effort="33.5" lower="-1.0471975511965976" upper="4.1887902047863905" velocity="21"/>
  </joint>
  <link name="HL_Y">
    <visual>
      <origin rpy="0.0 0.0 0.0" xyz="0.0 0.0 -0.1075"/>
      <geometry>
        <box size="0.034 0.0245 0.215"/>
      </geometry>
    </visual>
    <collision>
      <origin rpy="0.0 0.0 0.0" xyz="0.0 0.0 -0.1075"/>
      <geometry>
        <box size="0.034 0.0245 0.215"/>
      </geometry>
    </collision>
    <inertial>
      <origin rpy="0 0 0" xyz="0.002 0.014 -0.056"/>
      <mass value="0.272"/>
      <inertia ixx="0.001" ixy="0.0" ixz="0.0" iyy="0.002" iyz="0.0" izz="1e-05"/>
    </inertial>
  </link>
  <joint name="HL_KNEE_joint" type="revolute">
    <origin rpy="0.0 0.0 0.0" xyz="0.0 0.0 -0.215"/>
    <parent link="HL_Y"/>
    <child link="HL_KNEE"/>
    <axis xyz="0 1 0"/>
    <limit effort="33.5" lower="-2.6965336943312392" upper="-0.9162978572970231" velocity="21"/>
  </joint>
  <link name="HL_KNEE">
    <visual>
      <origin rpy="0.0 0.0 0.0" xyz="0.0 0.0 -0.104"/>
      <geometry>
        <box size="0.016 0.016 0.208"/>
      </geometry>
    </visual>
    <collision>
      <origin rpy="0.0 0.0 0.0" xyz="0.0 0.0 -0.104"/>
      <geometry>
        <box size="0.016 0.016 0.208"/>
      </geometry>
    </collision>
    <inertial>
      <origin rpy="0 0 0" xyz="0.0 0.0 -0.086"/>
      <mass value="0.157"/>
      <inertia ixx="0.001" ixy="0.0" ixz="0.0" iyy="0.001" iyz="0.0" izz="1e-05"/>
    </inertial>
  </link>
  <joint name="HL_FOOT_joint" type="fixed">
    <origin rpy="0.0 0.0 0.0" xyz="0.0 0.0 -0.22799999999999998"/>
    <parent link="HL_KNEE"/>
    <child link="HL_FOOT"/>
  </joint>
  <link name="HL_FOOT">
    <visual>
      <origin rpy="0 0 0" xyz="0 0 0"/>
      <geometry>
        <sphere radius="0.02"/>
      </geometry>
    </visual>
    <collision>
      <origin rpy="0 0 0" xyz="0 0 0"/>
      <geometry>
        <sphere radius="0.02"/>
      </geometry>
    </collision>
    <inertial>
      <mass value="0.06"/>
      <inertia ixx="9.600000000000001e-06" ixy="0.0" ixz="0.0" iyy="9.600000000000001e-06" iyz="0.0" izz="9.600000000000001e-06"/>
    </inertial>
  </link>
  <joint name="HR_X_joint" type="revolute">
    <origin rpy="0 0 0" xyz="-0.240292 -0.056 0"/>
    <parent link="body"/>
    <child link="HR_X"/>
    <axis xyz="1 0 0"/>
    <limit effort="33.5" lower="-0.8028514559173915" upper="0.8028514559173915" velocity="21"/>
  </joint>
  <link name="HR_X">
    <visual>
      <origin rpy="1.5707963267948966 0.0 0.0" xyz="0.0 -0.043425 0.0"/>
      <geometry>
        <cylinder length="0.08685" radius="0.046"/>
      </geometry>
    </visual>
    <collision>
      <origin rpy="1.5707963267948966 0.0 0.0" xyz="0.0 -0.043425 0.0"/>
      <geometry>
        <cylinder length="0.08685" radius="0.046"/>
      </geometry>
    </collision>
    <inertial>
      <origin rpy="0 0 0" xyz="0.002 -0.05 0.0"/>
      <mass value="1.508"/>
      <inertia ixx="0.003" ixy="0.0" ixz="0.0" iyy="0.002" iyz="0.0" izz="0.003"/>
    </inertial>
  </link>
  <joint name="HR_Y_joint" type="revolute">
    <origin rpy="0.0 0.0 0.0" xyz="0.0 -0.0991 0.0"/>
    <parent link="HR_X"/>
    <child link="HR_Y"/>
    <axis xyz="0 1 0"/>
    <limit effort="33.5" lower="-1.0471975511965976" upper="4.1887902047863905" velocity="21"/>
  </joint>
  <link name="HR_Y">
    <visual>
      <origin rpy="0.0 0.0 0.0" xyz="0.0 0.0 -0.1075"/>
      <geometry>
        <box size="0.034 0.0245 0.215"/>
      </geometry>
    </visual>
    <collision>
      <origin rpy="0.0 0.0 0.0" xyz="0.0 0.0 -0.1075"/>
      <geometry>
        <box size="0.034 0.0245 0.215"/>
      </geometry>
    </collision>
    <inertial>
      <origin rpy="0 0 0" xyz="0.002 -0.014 -0.056"/>
      <mass value="0.272"/>
      <inertia ixx="0.001" ixy="0.0" ixz="0.0" iyy="0.002" iyz="0.0" izz="1e-05"/>
    </inertial>
  </link>
  <joint name="HR_KNEE_joint" type="revolute">
    <origin rpy="0.0 0.0 0.0" xyz="0.0 0.0 -0.215"/>
    <parent link="HR_Y"/>
    <child link="HR_KNEE"/>
    <axis xyz="0 1 0"/>
    <limit effort="33.5" lower="-2.6965336943312392" upper="-0.9162978572970231" velocity="21"/>
  </joint>
  <link name="HR_KNEE">
    <visual>
      <origin rpy="0.0 0.0 0.0" xyz="0.0 0.0 -0.104"/>
      <geometry>
        <box size="0.016 0.016 0.208"/>
      </geometry>
    </visual>
    <collision>
      <origin rpy="0.0 0.0 0.0" xyz="0.0 0.0 -0.104"/>
      <geometry>
        <box size="0.016 0.016 0.208"/>
      </geometry>
    </collision>
    <inertial>
      <origin rpy="0 0 0" xyz="0.0 0.0 -0.086"/>
      <mass value="0.157"/>
      <inertia ixx="0.001" ixy="0.0" ixz="0.0" iyy="0.001" iyz="0.0" izz="1e-05"/>
    </inertial>
  </link>
  <joint name="HR_FOOT_joint" type="fixed">
    <origin rpy="0.0 0.0 0.0" xyz="0.0 0.0 -0.22799999999999998"/>
    <parent link="HR_KNEE"/>
    <child link="HR_FOOT"/>
  </joint>
  <link name="HR_FOOT">
    <visual>
      <origin rpy="0 0 0" xyz="0 0 0"/>
      <geometry>
        <sphere radius="0.02"/>
      </geometry>
    </visual>
    <collision>
      <origin rpy="0 0 0" xyz="0 0 0"/>
      <geometry>
        <sphere radius="0.02"/>
      </geometry>
    </collision>
    <inertial>
      <mass value="0.06"/>
      <inertia ixx="9.600000000000001e-06" ixy="0.0" ixz="0.0" iyy="9.600000000000001e-06" iyz="0.0" izz="9.600000000000001e-06"/>
    </inertial>
  </link>
</robot>
