<?xml version="1.0" ?>
<!-- =================================================================================== -->
<!-- |    This document was autogenerated by xacro from robot.xacro                    | -->
<!-- |    EDITING THIS FILE BY HAND IS NOT RECOMMENDED                                 | -->
<!-- =================================================================================== -->
<robot name="bupt_dog">
  <material name="black">
    <color rgba="0.0 0.0 0.0 1.0"/>
  </material>
  <material name="blue">
    <color rgba="0.0 0.0 0.8 1.0"/>
  </material>
  <material name="green">
    <color rgba="0.0 0.8 0.0 1.0"/>
  </material>
  <material name="grey">
    <color rgba="0.2 0.2 0.2 1.0"/>
  </material>
  <material name="silver">
    <color rgba="0.9137254901960784 0.9137254901960784 0.8470588235294118 1.0"/>
  </material>
  <material name="orange">
    <color rgba="1.0 0.4235294117647059 0.0392156862745098 1.0"/>
  </material>
  <material name="brown">
    <color rgba="0.8705882352941177 0.8117647058823529 0.7647058823529411 1.0"/>
  </material>
  <material name="red">
    <color rgba="0.8 0.0 0.0 1.0"/>
  </material>
  <material name="white">
    <color rgba="1.0 1.0 1.0 1.0"/>
  </material>
  <link name="body">
    <visual>
      <origin rpy="0 0 0" xyz="0 0 0"/>
      <geometry>
        <box size="0.362 0.26242 0.103"/>
      </geometry>
      <material name="black"/>
    </visual>
    <collision>
      <origin rpy="0 0 0" xyz="0 0 0"/>
      <geometry>
        <box size="0.362 0.26242 0.103"/>
      </geometry>
    </collision>
    <inertial>
      <origin rpy="0 0 0" xyz="0.0 0.0 0.0"/>
      <mass value="7.863"/>
      <inertia ixx="0.0522" ixy="0.0" ixz="0.0" iyy="0.0929" iyz="0.0" izz="0.130989"/>
    </inertial>
  </link>
  <joint name="FL_X_joint" type="revolute">
    <origin rpy="0 0 0" xyz="0.240292 0.056 0"/>
    <parent link="body"/>
    <child link="FL_X"/>
    <axis xyz="1 0 0"/>
    <limit effort="33.5" lower="-0.6981317007977318" upper="0.6981317007977318" velocity="21"/>
  </joint>
  <link name="FL_X">
    <visual>
      <origin rpy="1.5707963267948966 0.0 0.0" xyz="0.0 0.05155 0.0"/>
      <geometry>
        <cylinder length="0.1031" radius="0.046"/>
      </geometry>
      <material name="grey"/>
    </visual>
    <collision>
      <origin rpy="1.5707963267948966 0.0 0.0" xyz="0.0 0.05155 0.0"/>
      <geometry>
        <cylinder length="0.1031" radius="0.046"/>
      </geometry>
    </collision>
    <inertial>
      <origin rpy="0 0 0" xyz="0.002483 0.050399 6.1e-05"/>
      <mass value="1.440087"/>
      <inertia ixx="0.002386" ixy="0.0" ixz="0.0" iyy="0.001856" iyz="0.0" izz="0.002606"/>
    </inertial>
  </link>
  <joint name="FL_Y_joint" type="revolute">
    <origin rpy="0.0 0.0 0.0" xyz="0.0 0.1216 0.0"/>
    <parent link="FL_X"/>
    <child link="FL_Y"/>
    <axis xyz="0 1 0"/>
    <limit effort="33.5" lower="-0.17453292519943295" upper="2.0943951023931953" velocity="21"/>
  </joint>
  <link name="FL_Y">
    <visual>
      <origin rpy="0.0 0.0 0.0" xyz="0.0 0.0 -0.1075"/>
      <geometry>
        <box size="0.044 0.033 0.215"/>
      </geometry>
      <material name="white"/>
    </visual>
    <collision>
      <origin rpy="0.0 0.0 0.0" xyz="0.0 0.0 -0.1075"/>
      <geometry>
        <box size="0.044 0.033 0.215"/>
      </geometry>
    </collision>
    <inertial>
      <origin rpy="0 0 0" xyz="-0.006097 -0.010857 -0.071153"/>
      <mass value="0.272466"/>
      <inertia ixx="0.00148" ixy="0.0" ixz="0.0" iyy="0.001544" iyz="0.0" izz="0.000108"/>
    </inertial>
  </link>
  <joint name="FL_KNEE_joint" type="revolute">
    <origin rpy="0.0 0.0 0.0" xyz="0.0 0.0 -0.215"/>
    <parent link="FL_Y"/>
    <child link="FL_KNEE"/>
    <axis xyz="0 1 0"/>
    <limit effort="33.5" lower="-2.792526803190927" upper="-0.6108652381980153" velocity="21"/>
  </joint>
  <link name="FL_KNEE">
    <visual>
      <origin rpy="0.0 0.0 0.0" xyz="0.0 0.0 -0.114"/>
      <geometry>
        <box size="0.02977 0.0225 0.228"/>
      </geometry>
      <material name="white"/>
    </visual>
    <collision>
      <origin rpy="0.0 0.0 0.0" xyz="0.0 0.0 -0.114"/>
      <geometry>
        <box size="0.02977 0.0225 0.228"/>
      </geometry>
    </collision>
    <inertial>
      <origin rpy="0 0 0" xyz="-0.002252 0.0 -0.072067"/>
      <mass value="0.22"/>
      <inertia ixx="0.001255" ixy="0.0" ixz="0.0" iyy="0.001256" iyz="0.0" izz="3e-05"/>
    </inertial>
  </link>
  <joint name="FL_FOOT_joint" type="fixed" dont_collapse="true">
    <origin rpy="0.0 0.0 0.0" xyz="0.0 0.0 -0.228"/>
    <parent link="FL_KNEE"/>
    <child link="FL_FOOT"/>
  </joint>
  <link name="FL_FOOT">
    <visual>
      <origin rpy="0 0 0" xyz="0 0 0"/>
      <geometry>
        <sphere radius="0.02144"/>
      </geometry>
      <material name="white"/>
    </visual>
    <collision>
      <origin rpy="0 0 0" xyz="0 0 0"/>
      <geometry>
        <sphere radius="0.02144"/>
      </geometry>
    </collision>
    <inertial>
        <mass value="0.06"/>
        <inertia ixx="9.600000000000001e-06" ixy="0.0" ixz="0.0" iyy="9.600000000000001e-06" iyz="0.0" izz="9.600000000000001e-06"/>
    </inertial>
  </link>
  <joint name="FR_X_joint" type="revolute">
    <origin rpy="0 0 0" xyz="0.240292 -0.056 0"/>
    <parent link="body"/>
    <child link="FR_X"/>
    <axis xyz="1 0 0"/>
    <limit effort="33.5" lower="-0.6981317007977318" upper="0.6981317007977318" velocity="21"/>
  </joint>
  <link name="FR_X">
    <visual>
      <origin rpy="1.5707963267948966 0.0 0.0" xyz="0.0 -0.05155 0.0"/>
      <geometry>
        <cylinder length="0.1031" radius="0.046"/>
      </geometry>
      <material name="grey"/>
    </visual>
    <collision>
      <origin rpy="1.5707963267948966 0.0 0.0" xyz="0.0 -0.05155 0.0"/>
      <geometry>
        <cylinder length="0.1031" radius="0.046"/>
      </geometry>
    </collision>
    <inertial>
      <origin rpy="0 0 0" xyz="0.002483 -0.050399 6.1e-05"/>
      <mass value="1.440087"/>
      <inertia ixx="0.002386" ixy="0.0" ixz="0.0" iyy="0.001856" iyz="0.0" izz="0.002606"/>
    </inertial>
  </link>
  <joint name="FR_Y_joint" type="revolute">
    <origin rpy="0.0 0.0 0.0" xyz="0.0 -0.1216 0.0"/>
    <parent link="FR_X"/>
    <child link="FR_Y"/>
    <axis xyz="0 1 0"/>
    <limit effort="33.5" lower="-0.17453292519943295" upper="2.0943951023931953" velocity="21"/>
  </joint>
  <link name="FR_Y">
    <visual>
      <origin rpy="0.0 0.0 0.0" xyz="0.0 0.0 -0.1075"/>
      <geometry>
        <box size="0.044 0.033 0.215"/>
      </geometry>
      <material name="white"/>
    </visual>
    <collision>
      <origin rpy="0.0 0.0 0.0" xyz="0.0 0.0 -0.1075"/>
      <geometry>
        <box size="0.044 0.033 0.215"/>
      </geometry>
    </collision>
    <inertial>
      <origin rpy="0 0 0" xyz="-0.006097 0.010857 -0.071153"/>
      <mass value="0.272466"/>
      <inertia ixx="0.00148" ixy="0.0" ixz="0.0" iyy="0.001544" iyz="0.0" izz="0.000108"/>
    </inertial>
  </link>
  <joint name="FR_KNEE_joint" type="revolute">
    <origin rpy="0.0 0.0 0.0" xyz="0.0 0.0 -0.215"/>
    <parent link="FR_Y"/>
    <child link="FR_KNEE"/>
    <axis xyz="0 1 0"/>
    <limit effort="33.5" lower="-2.792526803190927" upper="-0.6108652381980153" velocity="21"/>
  </joint>
  <link name="FR_KNEE">
    <visual>
      <origin rpy="0.0 0.0 0.0" xyz="0.0 0.0 -0.114"/>
      <geometry>
        <box size="0.02977 0.0225 0.228"/>
      </geometry>
      <material name="white"/>
    </visual>
    <collision>
      <origin rpy="0.0 0.0 0.0" xyz="0.0 0.0 -0.114"/>
      <geometry>
        <box size="0.02977 0.0225 0.228"/>
      </geometry>
    </collision>
    <inertial>
      <origin rpy="0 0 0" xyz="-0.002252 0.0 -0.072067"/>
      <mass value="0.22"/>
      <inertia ixx="0.001255" ixy="0.0" ixz="0.0" iyy="0.001256" iyz="0.0" izz="3e-05"/>
    </inertial>
  </link>
  <joint name="FR_FOOT_joint" type="fixed" dont_collapse="true">
    <origin rpy="0.0 0.0 0.0" xyz="0.0 0.0 -0.228"/>
    <parent link="FR_KNEE"/>
    <child link="FR_FOOT"/>
  </joint>
  <link name="FR_FOOT">
    <visual>
      <origin rpy="0 0 0" xyz="0 0 0"/>
      <geometry>
        <sphere radius="0.02144"/>
      </geometry>
      <material name="white"/>
    </visual>
    <collision>
      <origin rpy="0 0 0" xyz="0 0 0"/>
      <geometry>
        <sphere radius="0.02144"/>
      </geometry>
    </collision>
    <inertial>
        <mass value="0.06"/>
        <inertia ixx="9.600000000000001e-06" ixy="0.0" ixz="0.0" iyy="9.600000000000001e-06" iyz="0.0" izz="9.600000000000001e-06"/>
    </inertial>
  </link>
  <joint name="HL_X_joint" type="revolute">
    <origin rpy="0 0 0" xyz="-0.240292 0.056 0"/>
    <parent link="body"/>
    <child link="HL_X"/>
    <axis xyz="1 0 0"/>
    <limit effort="33.5" lower="-0.6981317007977318" upper="0.6981317007977318" velocity="21"/>
  </joint>
  <link name="HL_X">
    <visual>
      <origin rpy="1.5707963267948966 0.0 0.0" xyz="0.0 0.05155 0.0"/>
      <geometry>
        <cylinder length="0.1031" radius="0.046"/>
      </geometry>
      <material name="grey"/>
    </visual>
    <collision>
      <origin rpy="1.5707963267948966 0.0 0.0" xyz="0.0 0.05155 0.0"/>
      <geometry>
        <cylinder length="0.1031" radius="0.046"/>
      </geometry>
    </collision>
    <inertial>
      <origin rpy="0 0 0" xyz="-0.002483 0.050399 6.1e-05"/>
      <mass value="1.440087"/>
      <inertia ixx="0.002386" ixy="0.0" ixz="0.0" iyy="0.001856" iyz="0.0" izz="0.002606"/>
    </inertial>
  </link>
  <joint name="HL_Y_joint" type="revolute">
    <origin rpy="0.0 0.0 0.0" xyz="0.0 0.1216 0.0"/>
    <parent link="HL_X"/>
    <child link="HL_Y"/>
    <axis xyz="0 1 0"/>
    <limit effort="33.5" lower="-0.17453292519943295" upper="2.0943951023931953" velocity="21"/>
  </joint>
  <link name="HL_Y">
    <visual>
      <origin rpy="0.0 0.0 0.0" xyz="0.0 0.0 -0.1075"/>
      <geometry>
        <box size="0.044 0.033 0.215"/>
      </geometry>
      <material name="white"/>
    </visual>
    <collision>
      <origin rpy="0.0 0.0 0.0" xyz="0.0 0.0 -0.1075"/>
      <geometry>
        <box size="0.044 0.033 0.215"/>
      </geometry>
    </collision>
    <inertial>
      <origin rpy="0 0 0" xyz="-0.006097 -0.010857 -0.071153"/>
      <mass value="0.272466"/>
      <inertia ixx="0.00148" ixy="0.0" ixz="0.0" iyy="0.001544" iyz="0.0" izz="0.000108"/>
    </inertial>
  </link>
  <joint name="HL_KNEE_joint" type="revolute">
    <origin rpy="0.0 0.0 0.0" xyz="0.0 0.0 -0.215"/>
    <parent link="HL_Y"/>
    <child link="HL_KNEE"/>
    <axis xyz="0 1 0"/>
    <limit effort="33.5" lower="-2.792526803190927" upper="-0.6108652381980153" velocity="21"/>
  </joint>
  <link name="HL_KNEE">
    <visual>
      <origin rpy="0.0 0.0 0.0" xyz="0.0 0.0 -0.114"/>
      <geometry>
        <box size="0.02977 0.0225 0.228"/>
      </geometry>
      <material name="white"/>
    </visual>
    <collision>
      <origin rpy="0.0 0.0 0.0" xyz="0.0 0.0 -0.114"/>
      <geometry>
        <box size="0.02977 0.0225 0.228"/>
      </geometry>
    </collision>
    <inertial>
      <origin rpy="0 0 0" xyz="-0.002252 0.0 -0.072067"/>
      <mass value="0.22"/>
      <inertia ixx="0.001255" ixy="0.0" ixz="0.0" iyy="0.001256" iyz="0.0" izz="3e-05"/>
    </inertial>
  </link>
  <joint name="HL_FOOT_joint" type="fixed" dont_collapse="true">
    <origin rpy="0.0 0.0 0.0" xyz="0.0 0.0 -0.228"/>
    <parent link="HL_KNEE"/>
    <child link="HL_FOOT"/>
  </joint>
  <link name="HL_FOOT">
    <visual>
      <origin rpy="0 0 0" xyz="0 0 0"/>
      <geometry>
        <sphere radius="0.02144"/>
      </geometry>
      <material name="white"/>
    </visual>
    <collision>
      <origin rpy="0 0 0" xyz="0 0 0"/>
      <geometry>
        <sphere radius="0.02144"/>
      </geometry>
    </collision>
    <inertial>
      <mass value="0.06"/>
      <inertia ixx="9.600000000000001e-06" ixy="0.0" ixz="0.0" iyy="9.600000000000001e-06" iyz="0.0" izz="9.600000000000001e-06"/>
    </inertial>
  </link>
  <joint name="HR_X_joint" type="revolute">
    <origin rpy="0 0 0" xyz="-0.240292 -0.056 0"/>
    <parent link="body"/>
    <child link="HR_X"/>
    <axis xyz="1 0 0"/>
    <limit effort="33.5" lower="-0.6981317007977318" upper="0.6981317007977318" velocity="21"/>
  </joint>
  <link name="HR_X">
    <visual>
      <origin rpy="1.5707963267948966 0.0 0.0" xyz="0.0 -0.05155 0.0"/>
      <geometry>
        <cylinder length="0.1031" radius="0.046"/>
      </geometry>
      <material name="grey"/>
    </visual>
    <collision>
      <origin rpy="1.5707963267948966 0.0 0.0" xyz="0.0 -0.05155 0.0"/>
      <geometry>
        <cylinder length="0.1031" radius="0.046"/>
      </geometry>
    </collision>
    <inertial>
      <origin rpy="0 0 0" xyz="-0.002483 -0.050399 6.1e-05"/>
      <mass value="1.440087"/>
      <inertia ixx="0.002386" ixy="0.0" ixz="0.0" iyy="0.001856" iyz="0.0" izz="0.002606"/>
    </inertial>
  </link>
  <joint name="HR_Y_joint" type="revolute">
    <origin rpy="0.0 0.0 0.0" xyz="0.0 -0.1216 0.0"/>
    <parent link="HR_X"/>
    <child link="HR_Y"/>
    <axis xyz="0 1 0"/>
    <limit effort="33.5" lower="-0.17453292519943295" upper="2.0943951023931953" velocity="21"/>
  </joint>
  <link name="HR_Y">
    <visual>
      <origin rpy="0.0 0.0 0.0" xyz="0.0 0.0 -0.1075"/>
      <geometry>
        <box size="0.044 0.033 0.215"/>
      </geometry>
      <material name="white"/>
    </visual>
    <collision>
      <origin rpy="0.0 0.0 0.0" xyz="0.0 0.0 -0.1075"/>
      <geometry>
        <box size="0.044 0.033 0.215"/>
      </geometry>
    </collision>
    <inertial>
      <origin rpy="0 0 0" xyz="-0.006097 0.010857 -0.071153"/>
      <mass value="0.272466"/>
      <inertia ixx="0.00148" ixy="0.0" ixz="0.0" iyy="0.001544" iyz="0.0" izz="0.000108"/>
    </inertial>
  </link>
  <joint name="HR_KNEE_joint" type="revolute">
    <origin rpy="0.0 0.0 0.0" xyz="0.0 0.0 -0.215"/>
    <parent link="HR_Y"/>
    <child link="HR_KNEE"/>
    <axis xyz="0 1 0"/>
    <limit effort="33.5" lower="-2.792526803190927" upper="-0.6108652381980153" velocity="21"/>
  </joint>
  <link name="HR_KNEE">
    <visual>
      <origin rpy="0.0 0.0 0.0" xyz="0.0 0.0 -0.114"/>
      <geometry>
        <box size="0.02977 0.0225 0.228"/>
      </geometry>
      <material name="white"/>
    </visual>
    <collision>
      <origin rpy="0.0 0.0 0.0" xyz="0.0 0.0 -0.114"/>
      <geometry>
        <box size="0.02977 0.0225 0.228"/>
      </geometry>
    </collision>
    <inertial>
      <origin rpy="0 0 0" xyz="-0.002252 0.0 -0.072067"/>
      <mass value="0.22"/>
      <inertia ixx="0.001255" ixy="0.0" ixz="0.0" iyy="0.001256" iyz="0.0" izz="3e-05"/>
    </inertial>
  </link>
  <joint name="HR_FOOT_joint" type="fixed" dont_collapse="true">
    <origin rpy="0.0 0.0 0.0" xyz="0.0 0.0 -0.228"/>
    <parent link="HR_KNEE"/>
    <child link="HR_FOOT"/>
  </joint>
  <link name="HR_FOOT">
    <visual>
      <origin rpy="0 0 0" xyz="0 0 0"/>
      <geometry>
        <sphere radius="0.02144"/>
      </geometry>
      <material name="white"/>
    </visual>
    <collision>
      <origin rpy="0 0 0" xyz="0 0 0"/>
      <geometry>
        <sphere radius="0.02144"/>
      </geometry>
    </collision>
    <inertial>
      <mass value="0.06"/>
      <inertia ixx="9.600000000000001e-06" ixy="0.0" ixz="0.0" iyy="9.600000000000001e-06" iyz="0.0" izz="9.600000000000001e-06"/>
    </inertial>
  </link>
</robot>

